<<<Analysis>>>
In the provided code, the `Test.test()` method is attempting to return `ValueError`, which is a Python built-in exception class. However, the method does not actually execute any code that would raise or return an instance of `ValueError`. Instead, it seems to be a mistake in the test method because it should either raise an exception or return a value computed by some operations, but directly returning the class `ValueError` itself is not meaningful in the context of typical unit tests or functional code.

The `BitStatusUtil` class contains methods for manipulating and checking bit states using bitwise operations. These methods include adding a state, checking if a state exists, removing a state, and a check method that validates the inputs. The check method raises a `ValueError` if any argument is negative or not even, but none of these methods are called in the `Test.test()` method.

Therefore, the return value of `Test.test()` is simply the reference to the exception class `ValueError`, not an instance of it, and no exception is raised or handled within the method itself.

<<<Output>>>
<class 'ValueError'>
[END-OF-RESPONSE]